Workbook

Sheet Dashboard
B1: Портфель вилл: начисления, деньги, качество данных
B2: Суммы в IDR. Жёлтые ячейки можно менять, остальное считается формулами из листов calc_*.
B4: Объект | C4: Все | D4: =IF(C4="Все","все 20 объектов",INDEX(properties!$C$2:$C$21,MATCH(C4,properties!$A$2:$A$21,0))&", собственник "&INDEX(properties!$D$2:$D$21,MATCH(C4,properties!$A$2:$A$21,0)))
B5: Период с | C5: 46266
B6: Период по | C6: 46326
B7: Учитывать брони «на проверке» | C7: Да | D7: «Нет» убирает брони с пересечением дат и отрицательной OTA fee: видно, насколько итог от них зависит
B9: Начисления за период (accrual, по ночам проживания) | C9: IDR | D9: как считается
B10: Gross bookings | C10: =IF($C$4="Все",SUM(calc_reservations!$AF$2:$AF$152),SUMIFS(calc_reservations!$AF$2:$AF$152,calc_reservations!$B$2:$B$152,$C$4)) | D10: gross × доля ночей в периоде
B11: − Возвраты | C11: =IF($C$4="Все",SUM(calc_reservations!$AG$2:$AG$152),SUMIFS(calc_reservations!$AG$2:$AG$152,calc_reservations!$B$2:$B$152,$C$4)) | D11: refund_amount × доля ночей
B12: Net booking value | C12: =C10-C11 | D12: gross − возвраты
B13: − OTA fees | C13: =IF($C$4="Все",SUM(calc_reservations!$AI$2:$AI$152),SUMIFS(calc_reservations!$AI$2:$AI$152,calc_reservations!$B$2:$B$152,$C$4)) | D13: ota_fee пропорционально оставшейся сумме (при полном возврате 0)
B14: − Management fee | C14: =IF($C$4="Все",SUM(calc_reservations!$AJ$2:$AJ$152),SUMIFS(calc_reservations!$AJ$2:$AJ$152,calc_reservations!$B$2:$B$152,$C$4)) | D14: ставка из commission_rules × net booking value
B15: − Операционные расходы | C15: =IF($C$4="Все",SUM(calc_expenses!$L$2:$L$91),SUMIFS(calc_expenses!$L$2:$L$91,calc_expenses!$B$2:$B$91,$C$4)) | D15: все расходы по expense_date, включая pending
B16: из них pending | C16: =IF($C$4="Все",SUM(calc_expenses!$N$2:$N$91),SUMIFS(calc_expenses!$N$2:$N$91,calc_expenses!$B$2:$B$91,$C$4)) | D16: ещё не оплачены
B17: Owner balance (оценка) | C17: =C12-C13-C14-C15 | D17: оценка: нет сальдо, выплат собственнику, налогов, см. README
B18: Ночей продано | C18: =IF($C$4="Все",SUM(calc_reservations!$AN$2:$AN$152),SUMIFS(calc_reservations!$AN$2:$AN$152,calc_reservations!$B$2:$B$152,$C$4)) | D18: при 20 виллах × 61 день доступно 1 220 ночей
B20: Деньги за период (cash) | C20: IDR | D20: как считается
B21: Начислено к получению (net − OTA) | C21: =C12-C13 | D21: то, что должно прийти от гостей/OTA за ночи периода
B22: Фактически поступило | C22: =IF($C$4="Все",SUM(calc_payments!$P$2:$P$77),SUMIFS(calc_payments!$P$2:$P$77,calc_payments!$C$2:$C$77,$C$4)) | D22: payments по payment_date, без дублей и нулей
B23: Разница: поступило − начислено | C23: =C22-C21 | D23: минус = денег пришло меньше, чем начислено
B24: Расходы оплачены (отток) | C24: =IF($C$4="Все",SUM(calc_expenses!$M$2:$M$91),SUMIFS(calc_expenses!$M$2:$M$91,calc_expenses!$B$2:$B$91,$C$4)) | D24: только payment_status = paid
B26: Сверка по броням, затронувшим период (полные суммы броней) | C26: IDR | D26: как считается
B27: Броней в периоде | C27: =IF($C$4="Все",COUNTIFS(calc_reservations!$AK$2:$AK$152,1),COUNTIFS(calc_reservations!$AK$2:$AK$152,1,calc_reservations!$B$2:$B$152,$C$4))
B28: Ожидалось по этим броням | C28: =IF($C$4="Все",SUM(calc_reservations!$AL$2:$AL$152),SUMIFS(calc_reservations!$AL$2:$AL$152,calc_reservations!$B$2:$B$152,$C$4)) | D28: net − OTA fee по каждой брони
B29: Получено по этим броням | C29: =IF($C$4="Все",SUM(calc_reservations!$AM$2:$AM$152),SUMIFS(calc_reservations!$AM$2:$AM$152,calc_reservations!$B$2:$B$152,$C$4)) | D29: платежи с тем же reservation_id, любая дата
B30: Разница | C30: =C29-C28
B31: Броней без платежа | C31: =IF($C$4="Все",COUNTIFS(calc_reservations!$AK$2:$AK$152,1,calc_reservations!$AC$2:$AC$152,"нет платежа"),COUNTIFS(calc_reservations!$AK$2:$AK$152,1,calc_reservations!$AC$2:$AC$152,"нет платежа",calc_reservations!$B$2:$B$152,$C$4)) | D31: фильтр «сверка» на листе calc_reservations
B32: Броней с расхождением суммы | C32: =IF($C$4="Все",COUNTIFS(calc_reservations!$AK$2:$AK$152,1,calc_reservations!$AC$2:$AC$152,"расхождение"),COUNTIFS(calc_reservations!$AK$2:$AK$152,1,calc_reservations!$AC$2:$AC$152,"расхождение",calc_reservations!$B$2:$B$152,$C$4))
B33: Броней «на проверке» среди них | C33: =IF($C$4="Все",COUNTIFS(calc_reservations!$AO$2:$AO$152,1),COUNTIFS(calc_reservations!$AO$2:$AO$152,1,calc_reservations!$B$2:$B$152,$C$4)) | D33: пересечение дат или OTA fee < 0
B35: Качество данных (все объекты, вне фильтров) | C35: IDR | D35: как считается
B36: Записей исключено | C36: =COUNTIF(calc_reservations!$Q$2:$Q$152,0)+COUNTIF(calc_payments!$M$2:$M$77,0)+COUNTIF(calc_expenses!$J$2:$J$91,0) | D36: брони + платежи + расходы; причины на листе dq_log
B37: Броней на проверке | C37: =SUM(calc_reservations!$S$2:$S$152) | D37: пересечение дат или OTA fee < 0
B38: Вопросов финдиректору | C38: =COUNTIF(dq_log!$G$2:$G$111,"Вопрос*")
B40: По объектам за выбранный период (фильтр «Объект» здесь не применяется)
B41: Объект | C41: Кластер | D41: Gross | E41: Возвраты | F41: Net | G41: OTA fees | H41: Mgmt fee | I41: Расходы | J41: Owner balance (оценка) | K41: Поступило | L41: Ночей | M41: На проверке
B42: =properties!A2&" · "&properties!C2 | C42: =properties!C2 | D42: =SUMIFS(calc_reservations!$AF$2:$AF$152,calc_reservations!$B$2:$B$152,properties!$A$2) | E42: =SUMIFS(calc_reservations!$AG$2:$AG$152,calc_reservations!$B$2:$B$152,properties!$A$2) | F42: =D42-E42 | G42: =SUMIFS(calc_reservations!$AI$2:$AI$152,calc_reservations!$B$2:$B$152,properties!$A$2) | H42: =SUMIFS(calc_reservations!$AJ$2:$AJ$152,calc_reservations!$B$2:$B$152,properties!$A$2) | I42: =SUMIFS(calc_expenses!$L$2:$L$91,calc_expenses!$B$2:$B$91,properties!$A$2) | J42: =F42-G42-H42-I42 | K42: =SUMIFS(calc_payments!$P$2:$P$77,calc_payments!$C$2:$C$77,properties!$A$2) | L42: =SUMIFS(calc_reservations!$AN$2:$AN$152,calc_reservations!$B$2:$B$152,properties!$A$2) | M42: =SUMIFS(calc_reservations!$AO$2:$AO$152,calc_reservations!$B$2:$B$152,properties!$A$2)
B43: =properties!A3&" · "&properties!C3 | C43: =properties!C3 | D43: =SUMIFS(calc_reservations!$AF$2:$AF$152,calc_reservations!$B$2:$B$152,properties!$A$3) | E43: =SUMIFS(calc_reservations!$AG$2:$AG$152,calc_reservations!$B$2:$B$152,properties!$A$3) | F43: =D43-E43 | G43: =SUMIFS(calc_reservations!$AI$2:$AI$152,calc_reservations!$B$2:$B$152,properties!$A$3) | H43: =SUMIFS(calc_reservations!$AJ$2:$AJ$152,calc_reservations!$B$2:$B$152,properties!$A$3) | I43: =SUMIFS(calc_expenses!$L$2:$L$91,calc_expenses!$B$2:$B$91,properties!$A$3) | J43: =F43-G43-H43-I43 | K43: =SUMIFS(calc_payments!$P$2:$P$77,calc_payments!$C$2:$C$77,properties!$A$3) | L43: =SUMIFS(calc_reservations!$AN$2:$AN$152,calc_reservations!$B$2:$B$152,properties!$A$3) | M43: =SUMIFS(calc_reservations!$AO$2:$AO$152,calc_reservations!$B$2:$B$152,properties!$A$3)
B44: =properties!A4&" · "&properties!C4 | C44: =properties!C4 | D44: =SUMIFS(calc_reservations!$AF$2:$AF$152,calc_reservations!$B$2:$B$152,properties!$A$4) | E44: =SUMIFS(calc_reservations!$AG$2:$AG$152,calc_reservations!$B$2:$B$152,properties!$A$4) | F44: =D44-E44 | G44: =SUMIFS(calc_reservations!$AI$2:$AI$152,calc_reservations!$B$2:$B$152,properties!$A$4) | H44: =SUMIFS(calc_reservations!$AJ$2:$AJ$152,calc_reservations!$B$2:$B$152,properties!$A$4) | I44: =SUMIFS(calc_expenses!$L$2:$L$91,calc_expenses!$B$2:$B$91,properties!$A$4) | J44: =F44-G44-H44-I44 | K44: =SUMIFS(calc_payments!$P$2:$P$77,calc_payments!$C$2:$C$77,properties!$A$4) | L44: =SUMIFS(calc_reservations!$AN$2:$AN$152,calc_reservations!$B$2:$B$152,properties!$A$4) | M44: =SUMIFS(calc_reservations!$AO$2:$AO$152,calc_reservations!$B$2:$B$152,properties!$A$4)
B45: =properties!A5&" · "&properties!C5 | C45: =properties!C5 | D45: =SUMIFS(calc_reservations!$AF$2:$AF$152,calc_reservations!$B$2:$B$152,properties!$A$5) | E45: =SUMIFS(calc_reservations!$AG$2:$AG$152,calc_reservations!$B$2:$B$152,properties!$A$5) | F45: =D45-E45 | G45: =SUMIFS(calc_reservations!$AI$2:$AI$152,calc_reservations!$B$2:$B$152,properties!$A$5) | H45: =SUMIFS(calc_reservations!$AJ$2:$AJ$152,calc_reservations!$B$2:$B$152,properties!$A$5) | I45: =SUMIFS(calc_expenses!$L$2:$L$91,calc_expenses!$B$2:$B$91,properties!$A$5) | J45: =F45-G45-H45-I45 | K45: =SUMIFS(calc_payments!$P$2:$P$77,calc_payments!$C$2:$C$77,properties!$A$5) | L45: =SUMIFS(calc_reservations!$AN$2:$AN$152,calc_reservations!$B$2:$B$152,properties!$A$5) | M45: =SUMIFS(calc_reservations!$AO$2:$AO$152,calc_reservations!$B$2:$B$152,properties!$A$5)
B46: =properties!A6&" · "&properties!C6 | C46: =properties!C6 | D46: =SUMIFS(calc_reservations!$AF$2:$AF$152,calc_reservations!$B$2:$B$152,properties!$A$6) | E46: =SUMIFS(calc_reservations!$AG$2:$AG$152,calc_reservations!$B$2:$B$152,properties!$A$6) | F46: =D46-E46 | G46: =SUMIFS(calc_reservations!$AI$2:$AI$152,calc_reservations!$B$2:$B$152,properties!$A$6) | H46: =SUMIFS(calc_reservations!$AJ$2:$AJ$152,calc_reservations!$B$2:$B$152,properties!$A$6) | I46: =SUMIFS(calc_expenses!$L$2:$L$91,calc_expenses!$B$2:$B$91,properties!$A$6) | J46: =F46-G46-H46-I46 | K46: =SUMIFS(calc_payments!$P$2:$P$77,calc_payments!$C$2:$C$77,properties!$A$6) | L46: =SUMIFS(calc_reservations!$AN$2:$AN$152,calc_reservations!$B$2:$B$152,properties!$A$6) | M46: =SUMIFS(calc_reservations!$AO$2:$AO$152,calc_reservations!$B$2:$B$152,properties!$A$6)
...

Sheet Методология
B1: Методология, допущения и архитектура
B2: Прототип в рамках тестового задания на 2–3 часа: рабочее ядро расчёта, диагностика данных и схема дальнейшей системы. Production-система не делалась.
B4: 1. Финансовая логика
B5: Показатель | C5: Формула | D5: Где в таблице
B6: Доля брони в периоде | C6: ночей в периоде / всего ночей брони. Ночь — дата от check_in включительно до check_out не включая | D6: calc_reservations: AD, AE
B7: Gross bookings | C7: gross_booking_value × доля | D7: calc_reservations: AF
B8: Net booking value | C8: gross − refund_amount | D8: calc_reservations: W, AH
B9: OTA fees | C9: ota_fee × net / gross (при полном возврате = 0) | D9: calc_reservations: X, AI
B10: Management fee | C10: ставка из commission_rules по объекту и дате check_in × net | D10: calc_reservations: V, Y, AJ
B11: Операционные расходы | C11: amount по expense_date, включая pending | D11: calc_expenses: L
B12: Owner balance (оценка) | C12: net − OTA fees − management fee − расходы | D12: Dashboard: C17
B13: Начислено к получению | C13: net − OTA fees (платёж приходит уже за вычетом ota_fee) | D13: Dashboard: C21
B14: Поступило | C14: payments по payment_date, без дублей, нулей и неизвестных объектов | D14: calc_payments: P
B16: 2. Правила обработки
B17: Признание выручки | C17: По ночам проживания, как требует МСФО (IFRS) 15: услуга проживания оказывается во времени, каждую ночь. Для сравнения, по дате выезда gross сентября 683 262 688 вместо 757 178 005, октября 636 261 198 вместо 585 637 031, а 23 291 150 уходят в ноябрь (R0003, R0052).
B18: Выручка и деньги | C18: Начисления привязаны к ночам проживания, деньги — к дате платежа. Это разные числа, на дашборде они в разных блоках и не складываются.
B19: Отмены | C19: Все 12 отмен имеют refund = gross. Net = 0, management fee = 0. OTA fee сторнируется пропорционально оставшейся сумме — допущение, вынесено в вопросы.
B20: Возвраты | C20: Уменьшают net и базу management fee. Возврат больше суммы брони или возврат при статусе confirmed — запись исключается и уходит на проверку.
B21: Даты | C21: Бронь, переходящая через границу месяца, делится по ночам. Бронь с выездом 01.11 целиком относится к октябрю. Платёж учитывается в периоде по payment_date.
B22: Комиссия УК | C22: База — gross_booking_value. По правилу «OTA fees are separate» комиссия OTA базу не уменьшает. Ставка 17%, для вилл Bukit 20%.
B23: Расходы | C23: В начисления попадают все, в отток денег — только paid. Pending показан отдельно.
B24: Качество данных | C24: Исключено — не в расчёте. На проверке — в расчёте, но помечено; на Dashboard можно выключить. Вопрос — решение за финансами. Список на листе dq_log.
B26: 3. Почему owner balance — оценка
C27: Нет начального сальдо и выплат собственнику
C28: Нет налогов и правила, кто их платит
C29: Нет правил удержаний при отменах
C30: Нет курса валют для броней не в IDR
C31: Не определено, какие расходы несёт собственник
C32: Неизвестна дата среза данных
B34: 4. Архитектура будущей системы
B54: Этап | C54: Что происходит | D54: Инструменты (вариант)
B55: Источники | C55: Channel manager / OTA, PMS, банковские выписки, учёт расходов, договоры со ставками | D55: API, CSV-выгрузки
B56: Загрузка | C56: Импорт по расписанию в raw-слой: данные как пришли, с load_id и хешем файла | D56: n8n / Airbyte / Apps Script
B57: Проверка и хранение | C57: Staging (типы), DQ-правила, карантин для ошибок, core с версиями записей и справочниками | D57: Postgres или BigQuery
B58: Расчёты | C58: Ночи и доли периода, комиссии, сверка с платежами, owner statement — одна версия логики | D58: SQL / dbt
B59: Dashboard | C59: Финансы видят всё и качество данных, собственники — только свои виллы | D59: Metabase / Looker Studio
B61: Повторный импорт без дублей | C61: Файл с тем же хешем не грузится повторно. Запись в core определяется ключом (source + reservation_id, payment_id, expense_id) и пишется через upsert. Более поздний updated_at создаёт новую версию, идентичная строка игнорируется.
B62: Аудит изменений | C62: Raw не меняется. У строк core есть load_id, valid_from, valid_to. Исправления — отдельными корректировками с автором и причиной. Решения по карантину пишутся в журнал, закрытый месяц блокируется.
B63: Разграничение доступа | C63: Роли: финансы, операционная команда, собственник (row-level security по owner_id, только чтение), администратор. Загрузка под сервисной учётной записью, ключи в secret manager.
B65: 5. Вопросы финансовому директору
...

Sheet dq_log
A1: № | B1: Таблица | C1: Запись | D1: Строка CSV | E1: Проверка | F1: Что не так | G1: Решение | H1: Влияние на расчёт
A2: 1 | B2: reservations | C2: R0034 | D2: 35 | E2: Некорректный ID | F2: Объект V999 отсутствует в properties.csv | G2: Исключено + на проверку | H2: Нельзя отнести собственнику и ставке комиссии
A3: 2 | B3: reservations | C3: R0061 | D3: 62 | E3: Валюта | F3: Валюта USD при этом base_currency объекта IDR а сумма 4 280 874 по масштабу похожа на рупии | G3: Исключено + на проверку | H3: Курса в данных нет; пересчитывать или менять валюту молча нельзя
A4: 3 | B4: reservations | C4: R0072 | D4: 73 | E4: Арифметика | F4: Статус confirmed но refund 7 970 068 больше gross 7 070 068 ровно на 900 000 (похоже на опечатку в одной цифре: 7 970 068 вместо 7 070 068); платёж по брони 0. Скорее всего это отмена с полным возвратом | G4: Исключено + на проверку | H4: Неясно, была ли выручка; net получился бы отрицательным (−900 000)
A5: 4 | B5: reservations | C5: R0015 | D5: 152 | E5: Дубль | F5: Строка полностью повторяет строку 16 | G5: Исключено | H5: Вторая копия не считается, иначе gross завышен на 13 628 994
A6: 5 | B6: reservations | C6: R0102 | D6: 103 | E6: Арифметика | F6: Отрицательная ota_fee -100 000; поступление больше gross | G6: На проверке (в расчёте как есть) | H6: Влияние на OTA fees: −100 000 IDR
A7: 6 | B7: reservations | C7: R0001 | D7: 2 | E7: Пересечение периодов | F7: V013 2026-09-22–2026-09-25 пересекается с: R0090, R0119. | G7: На проверке (в расчёте) | H7: Вилла не может быть занята дважды; переключатель на Dashboard показывает итог без этих броней
A8: 7 | B8: reservations | C8: R0002 | D8: 3 | E8: Пересечение периодов | F8: V019 2026-10-15–2026-10-19 пересекается с: R0037. | G8: На проверке (в расчёте) | H8: Вилла не может быть занята дважды; переключатель на Dashboard показывает итог без этих броней
A9: 8 | B9: reservations | C9: R0005 | D9: 6 | E9: Пересечение периодов | F9: V005 2026-09-10–2026-09-17 пересекается с: R0098. | G9: На проверке (в расчёте) | H9: Вилла не может быть занята дважды; переключатель на Dashboard показывает итог без этих броней
A10: 9 | B10: reservations | C10: R0007 | D10: 8 | E10: Пересечение периодов | F10: V002 2026-09-08–2026-09-16 пересекается с: R0059. | G10: На проверке (в расчёте) | H10: Вилла не может быть занята дважды; переключатель на Dashboard показывает итог без этих броней
A11: 10 | B11: reservations | C11: R0008 | D11: 9 | E11: Пересечение периодов | F11: V014 2026-10-26–2026-10-30 пересекается с: R0050. | G11: На проверке (в расчёте) | H11: Вилла не может быть занята дважды; переключатель на Dashboard показывает итог без этих броней
A12: 11 | B12: reservations | C12: R0010 | D12: 11 | E12: Пересечение периодов | F12: V005 2026-10-06–2026-10-13 пересекается с: R0088, R0117. | G12: На проверке (в расчёте) | H12: Вилла не может быть занята дважды; переключатель на Dashboard показывает итог без этих броней
A13: 12 | B13: reservations | C13: R0011 | D13: 12 | E13: Пересечение периодов | F13: V004 2026-09-10–2026-09-17 пересекается с: R0024. | G13: На проверке (в расчёте) | H13: Вилла не может быть занята дважды; переключатель на Dashboard показывает итог без этих броней
... A92: 91 | B92: reservations | C92: R0150 | D92: 151 | E92: Пересечение периодов | F92: V009 2026-09-01–2026-09-09 пересекается с: R0149. Статус modified без ссылки на исходную бронь. | G92: На проверке (в расчёте) | H92: Вилла не может быть занята дважды; переключатель на Dashboard показывает итог без этих броней
A93: 92 | B93: reservations | C93: R0149, R0150 | D93: 149, 150 | E93: Скрытый дубль | F93: Обе брони modified, V009, почти одни даты (09-01/09-02 → 09-09), разный gross. Похоже на две версии одной брони; платёж есть только по R0150 | G93: На проверке (в расчёте) | H93: Если R0149 — старая версия, выручка V009 завышена на 14 235 106
A94: 93 | B94: reservations | C94: R0033, R0056 | D94: 34, 57 | E94: Скрытый дубль | F94: V008, одинаковые даты 2026-09-25 → 2026-10-02, разные суммы (14 606 373 и 5 624 162). Платёж только по R0056 | G94: На проверке (в расчёте) | H94: Двойное бронирование или дубль с ошибкой в сумме
A95: 94 | B95: reservations | C95: все cancelled | E95: Логика | F95: У 12 отменённых броней заполнена ota_fee, при этом refund = gross (полный возврат) | G95: Вопрос финдиректору (допущение в расчёте) | H95: OTA fee по отмене считаю сторнированной: fee × (gross − refund) / gross = 0. Вопрос финдиректору: удерживает ли OTA комиссию
A96: 95 | B96: reservations | C96: все Direct | E96: Логика | F96: У 30 прямых броней (channel=Direct) заполнена ota_fee 12–17% | G96: Вопрос финдиректору (в расчёте как есть) | H96: Если это не OTA, а эквайринг или ошибка, OTA fees завышены
A97: 96 | B97: reservations | C97: R0143, R0144, R0145, R0146, R0147, R0148, R0149, R0150 | E97: Логика | F97: Статус modified без ссылки на исходную бронь; исходная версия могла остаться в данных как confirmed | G97: Инфо (в расчёте как текущая версия) | H97: Возможен двойной учёт, см. пересечения
A98: 97 | B98: payments | C98: P0017 | D98: 18 | E98: Некорректный ID | F98: Объект V999 (бронь R0034) отсутствует в properties.csv | G98: Исключено + на проверку | H98: Деньги поступили, но не отнесены ни к одному объекту
A99: 98 | B99: payments | C99: P0036 | D99: 37 | E99: Арифметика | F99: Сумма 0 со статусом received (бронь R0072, confirmed) | G99: Исключено | H99: Не поступление; на суммы не влияет, но искажает число платежей
A100: 99 | B100: payments | C100: P0066 | D100: 67 | E100: Арифметика | F100: Сумма 0 со статусом received (бронь R0132, cancelled) | G100: Исключено | H100: Не поступление; на суммы не влияет, но искажает число платежей
A101: 100 | B101: payments | C101: P0067 | D101: 68 | E101: Арифметика | F101: Сумма 0 со статусом received (бронь R0134, cancelled) | G101: Исключено | H101: Не поступление; на суммы не влияет, но искажает число платежей
A102: 101 | B102: payments | C102: P0068 | D102: 69 | E102: Арифметика | F102: Сумма 0 со статусом received (бронь R0136, cancelled) | G102: Исключено | H102: Не поступление; на суммы не влияет, но искажает число платежей
A103: 102 | B103: payments | C103: P0069 | D103: 70 | E103: Арифметика | F103: Сумма 0 со статусом received (бронь R0138, cancelled) | G103: Исключено | H103: Не поступление; на суммы не влияет, но искажает число платежей
A104: 103 | B104: payments | C104: P0070 | D104: 71 | E104: Арифметика | F104: Сумма 0 со статусом received (бронь R0140, cancelled) | G104: Исключено | H104: Не поступление; на суммы не влияет, но искажает число платежей
A105: 104 | B105: payments | C105: P0071 | D105: 72 | E105: Арифметика | F105: Сумма 0 со статусом received (бронь R0142, cancelled) | G105: Исключено | H105: Не поступление; на суммы не влияет, но искажает число платежей
A106: 105 | B106: payments | C106: P0075 | D106: 77 | E106: Дубль | F106: Строка полностью повторяет предыдущую | G106: Исключено | H106: Иначе поступления завышены на 12 211 055
A107: 106 | B107: payments | C107: P0004, P0008, P0072 | E107: Даты | F107: Платёж в ноябре по брони с выездом в октябре | G107: Инфо | H107: В кэше за сентябрь–октябрь не видны, хотя выручка начислена; это разница метода, не ошибка
A108: 107 | B108: payments | C108: 19 платежей | E108: Даты | F108: Последний updated_at в reservations — 2026-10-15, но 19 платежей со статусом received датированы позже (до 2026-11-05) | G108: Вопрос финдиректору (в расчёте) | H108: Если выгрузка от 15.10, эти «поступления» — будущие или плановые, а не факт. Нужна дата среза
A109: 108 | B109: payments | C109: нечётные R | E109: Полнота | F109: Платежи есть только для броней с чётным номером (75 из 150) | G109: Вопрос финдиректору | H109: Разница «начислено − поступило» в основном из-за неполной выгрузки, а не долга
A110: 109 | B110: expenses | C110: E0017 | D110: 18 | E110: Некорректный ID | F110: Объект V777 отсутствует в properties.csv | G110: Исключено + на проверку | H110: 834 779 IDR не отнесены ни к одному собственнику
A111: 110 | B111: expenses | C111: pending | E111: Логика | F111: Часть расходов в статусе pending | G111: Инфо | H111: В начислениях учтены все, в оттоке денег только paid; показаны отдельно

Sheet calc_reservations
A1: reservation_id | B1: property_id | C1: check_in | D1: check_out | E1: status | F1: gross | G1: currency | H1: ota_fee | I1: refund | J1: channel | K1: nights | L1: chk: дубль ID | M1: chk: нет объекта | N1: chk: валюта | O1: chk: возврат | P1: chk: OTA<0 | Q1: база (не исключена) | R1: пересечений | S1: на проверке | T1: в расчёте | U1: решение | V1: ставка УК | W1: net booking | X1: OTA fee (с учётом возврата) | Y1: management fee | Z1: ожидаемая выплата | AA1: получено по брони | AB1: разница | AC1: сверка | AD1: ночей в периоде | AE1: доля в периоде | AF1: gross · период | AG1: refund · период | AH1: net · период | AI1: OTA · период | AJ1: mgmt · период | AK1: бронь в периоде | AL1: ожидалось · брони периода | AM1: получено · брони периода | AN1: ночей · период (в расчёте) | AO1: на проверке · период
A2: =raw_reservations!A2 | B2: =raw_reservations!B2 | C2: =raw_reservations!C2 | D2: =raw_reservations!D2 | E2: =raw_reservations!E2 | F2: =raw_reservations!F2 | G2: =raw_reservations!G2 | H2: =raw_reservations!H2 | ... J2: =raw_reservations!J2 | K2: =D2-C2 | L2: =IF(COUNTIF(A$2:A2,A2)>1,1,0) | M2: =IF(COUNTIF(properties!$A$2:$A$21,B2)=0,1,0) | N2: =IF(M2=1,0,IF(G2<>INDEX(properties!$E$2:$E$21,MATCH(B2,properties!$A$2:$A$21,0)),1,0)) | O2: =IF(OR(I2>F2,AND(E2<>"cancelled",I2>0)),1,0) | P2: =IF(H2<0,1,0) | Q2: =IF(L2+M2+N2+O2=0,1,0) | R2: =IF(AND(Q2=1,E2<>"cancelled"),COUNTIFS($B$2:$B$152,B2,$Q$2:$Q$152,1,$E$2:$E$152,"<>cancelled",$C$2:$C$152,"<"&D2,$D$2:$D$152,">"&C2)-1,0) | S2: =IF(AND(Q2=1,OR(R2>0,P2=1)),1,0) | T2: =IF(Q2=0,0,IF(AND(S2=1,Dashboard!$C$7="Нет"),0,1)) | U2: =IF(L2=1,"Исключено: дубль",IF(M2=1,"Исключено: нет объекта",IF(N2=1,"Исключено: валюта",IF(O2=1,"Исключено: возврат/статус",IF(S2=1,"На проверке","OK"))))) | V2: =SUMIFS(commission_rules!$D$2:$D$21,commission_rules!$A$2:$A$21,B2,commission_rules!$B$2:$B$21,"<="&C2,commission_rules!$C$2:$C$21,">="&C2) | W2: =F2-I2 | X2: =IF(F2=0,0,H2*W2/F2) | Y2: =V2*W2 | Z2: =W2-X2 | AA2: =SUMIFS(calc_payments!$N$2:$N$77,calc_payments!$B$2:$B$77,A2) | AB2: =AA2-Z2 | AC2: =IF(T2=0,"",IF(AA2=0,IF(Z2=0,"нечего получать","нет платежа"),IF(ABS(AB2)<1,"сходится","расхождение"))) | AD2: =MAX(0,MIN(D2,Dashboard!$C$6+1)-MAX(C2,Dashboard!$C$5)) | AE2: =IF(K2=0,0,AD2/K2)*T2 | AF2: =F2*AE2 | AG2: =I2*AE2 | AH2: =W2*AE2 | AI2: =X2*AE2 | AJ2: =Y2*AE2 | AK2: =IF(AND(T2=1,AD2>0),1,0) | AL2: =Z2*AK2 | AM2: =AA2*AK2 | AN2: =AD2*T2 | AO2: =S2*AK2
A3: =raw_reservations!A3 | B3: =raw_reservations!B3 | C3: =raw_reservations!C3 | D3: =raw_reservations!D3 | E3: =raw_reservations!E3 | F3: =raw_reservations!F3 | G3: =raw_reservations!G3 | H3: =raw_reservations!H3 | ... J3: =raw_reservations!J3 | K3: =D3-C3 | L3: =IF(COUNTIF(A$2:A3,A3)>1,1,0) | M3: =IF(COUNTIF(properties!$A$2:$A$21,B3)=0,1,0) | N3: =IF(M3=1,0,IF(G3<>INDEX(properties!$E$2:$E$21,MATCH(B3,properties!$A$2:$A$21,0)),1,0)) | O3: =IF(OR(I3>F3,AND(E3<>"cancelled",I3>0)),1,0) | P3: =IF(H3<0,1,0) | Q3: =IF(L3+M3+N3+O3=0,1,0) | R3: =IF(AND(Q3=1,E3<>"cancelled"),COUNTIFS($B$2:$B$152,B3,$Q$2:$Q$152,1,$E$2:$E$152,"<>cancelled",$C$2:$C$152,"<"&D3,$D$2:$D$152,">"&C3)-1,0) | S3: =IF(AND(Q3=1,OR(R3>0,P3=1)),1,0) | T3: =IF(Q3=0,0,IF(AND(S3=1,Dashboard!$C$7="Нет"),0,1)) | U3: =IF(L3=1,"Исключено: дубль",IF(M3=1,"Исключено: нет объекта",IF(N3=1,"Исключено: валюта",IF(O3=1,"Исключено: возврат/статус",IF(S3=1,"На проверке","OK"))))) | V3: =SUMIFS(commission_rules!$D$2:$D$21,commission_rules!$A$2:$A$21,B3,commission_rules!$B$2:$B$21,"<="&C3,commission_rules!$C$2:$C$21,">="&C3) | W3: =F3-I3 | X3: =IF(F3=0,0,H3*W3/F3) | Y3: =V3*W3 | Z3: =W3-X3 | AA3: =SUMIFS(calc_payments!$N$2:$N$77,calc_payments!$B$2:$B$77,A3) | AB3: =AA3-Z3 | AC3: =IF(T3=0,"",IF(AA3=0,IF(Z3=0,"нечего получать","нет платежа"),IF(ABS(AB3)<1,"сходится","расхождение"))) | AD3: =MAX(0,MIN(D3,Dashboard!$C$6+1)-MAX(C3,Dashboard!$C$5)) | AE3: =IF(K3=0,0,AD3/K3)*T3 | AF3: =F3*AE3 | AG3: =I3*AE3 | AH3: =W3*AE3 | AI3: =X3*AE3 | AJ3: =Y3*AE3 | AK3: =IF(AND(T3=1,AD3>0),1,0) | AL3: =Z3*AK3 | AM3: =AA3*AK3 | AN3: =AD3*T3 | AO3: =S3*AK3
A4: =raw_reservations!A4 | B4: =raw_reservations!B4 | C4: =raw_reservations!C4 | D4: =raw_reservations!D4 | E4: =raw_reservations!E4 | F4: =raw_reservations!F4 | G4: =raw_reservations!G4 | H4: =raw_reservations!H4 | ... J4: =raw_reservations!J4 | K4: =D4-C4 | L4: =IF(COUNTIF(A$2:A4,A4)>1,1,0) | M4: =IF(COUNTIF(properties!$A$2:$A$21,B4)=0,1,0) | N4: =IF(M4=1,0,IF(G4<>INDEX(properties!$E$2:$E$21,MATCH(B4,properties!$A$2:$A$21,0)),1,0)) | O4: =IF(OR(I4>F4,AND(E4<>"cancelled",I4>0)),1,0) | P4: =IF(H4<0,1,0) | Q4: =IF(L4+M4+N4+O4=0,1,0) | R4: =IF(AND(Q4=1,E4<>"cancelled"),COUNTIFS($B$2:$B$152,B4,$Q$2:$Q$152,1,$E$2:$E$152,"<>cancelled",$C$2:$C$152,"<"&D4,$D$2:$D$152,">"&C4)-1,0) | S4: =IF(AND(Q4=1,OR(R4>0,P4=1)),1,0) | T4: =IF(Q4=0,0,IF(AND(S4=1,Dashboard!$C$7="Нет"),0,1)) | U4: =IF(L4=1,"Исключено: дубль",IF(M4=1,"Исключено: нет объекта",IF(N4=1,"Исключено: валюта",IF(O4=1,"Исключено: возврат/статус",IF(S4=1,"На проверке","OK"))))) | V4: =SUMIFS(commission_rules!$D$2:$D$21,commission_rules!$A$2:$A$21,B4,commission_rules!$B$2:$B$21,"<="&C4,commission_rules!$C$2:$C$21,">="&C4) | W4: =F4-I4 | X4: =IF(F4=0,0,H4*W4/F4) | Y4: =V4*W4 | Z4: =W4-X4 | AA4: =SUMIFS(calc_payments!$N$2:$N$77,calc_payments!$B$2:$B$77,A4) | AB4: =AA4-Z4 | AC4: =IF(T4=0,"",IF(AA4=0,IF(Z4=0,"нечего получать","нет платежа"),IF(ABS(AB4)<1,"сходится","расхождение"))) | AD4: =MAX(0,MIN(D4,Dashboard!$C$6+1)-MAX(C4,Dashboard!$C$5)) | AE4: =IF(K4=0,0,AD4/K4)*T4 | AF4: =F4*AE4 | AG4: =I4*AE4 | AH4: =W4*AE4 | AI4: =X4*AE4 | AJ4: =Y4*AE4 | AK4: =IF(AND(T4=1,AD4>0),1,0) | AL4: =Z4*AK4 | AM4: =AA4*AK4 | AN4: =AD4*T4 | AO4: =S4*AK4
A5: =raw_reservations!A5 | B5: =raw_reservations!B5 | C5: =raw_reservations!C5 | D5: =raw_reservations!D5 | E5: =raw_reservations!E5 | F5: =raw_reservations!F5 | G5: =raw_reservations!G5 | H5: =raw_reservations!H5 | ... J5: =raw_reservations!J5 | K5: =D5-C5 | L5: =IF(COUNTIF(A$2:A5,A5)>1,1,0) | M5: =IF(COUNTIF(properties!$A$2:$A$21,B5)=0,1,0) | N5: =IF(M5=1,0,IF(G5<>INDEX(properties!$E$2:$E$21,MATCH(B5,properties!$A$2:$A$21,0)),1,0)) | O5: =IF(OR(I5>F5,AND(E5<>"cancelled",I5>0)),1,0) | P5: =IF(H5<0,1,0) | Q5: =IF(L5+M5+N5+O5=0,1,0) | R5: =IF(AND(Q5=1,E5<>"cancelled"),COUNTIFS($B$2:$B$152,B5,$Q$2:$Q$152,1,$E$2:$E$152,"<>cancelled",$C$2:$C$152,"<"&D5,$D$2:$D$152,">"&C5)-1,0) | S5: =IF(AND(Q5=1,OR(R5>0,P5=1)),1,0) | T5: =IF(Q5=0,0,IF(AND(S5=1,Dashboard!$C$7="Нет"),0,1)) | U5: =IF(L5=1,"Исключено: дубль",IF(M5=1,"Исключено: нет объекта",IF(N5=1,"Исключено: валюта",IF(O5=1,"Исключено: возврат/статус",IF(S5=1,"На проверке","OK"))))) | V5: =SUMIFS(commission_rules!$D$2:$D$21,commission_rules!$A$2:$A$21,B5,commission_rules!$B$2:$B$21,"<="&C5,commission_rules!$C$2:$C$21,">="&C5) | W5: =F5-I5 | X5: =IF(F5=0,0,H5*W5/F5) | Y5: =V5*W5 | Z5: =W5-X5 | AA5: =SUMIFS(calc_payments!$N$2:$N$77,calc_payments!$B$2:$B$77,A5) | AB5: =AA5-Z5 | AC5: =IF(T5=0,"",IF(AA5=0,IF(Z5=0,"нечего получать","нет платежа"),IF(ABS(AB5)<1,"сходится","расхождение"))) | AD5: =MAX(0,MIN(D5,Dashboard!$C$6+1)-MAX(C5,Dashboard!$C$5)) | AE5: =IF(K5=0,0,AD5/K5)*T5 | AF5: =F5*AE5 | AG5: =I5*AE5 | AH5: =W5*AE5 | AI5: =X5*AE5 | AJ5: =Y5*AE5 | AK5: =IF(AND(T5=1,AD5>0),1,0) | AL5: =Z5*AK5 | AM5: =AA5*AK5 | AN5: =AD5*T5 | AO5: =S5*AK5
A6: =raw_reservations!A6 | B6: =raw_reservations!B6 | C6: =raw_reservations!C6 | D6: =raw_reservations!D6 | E6: =raw_reservations!E6 | F6: =raw_reservations!F6 | G6: =raw_reservations!G6 | H6: =raw_reservations!H6 | ... J6: =raw_reservations!J6 | K6: =D6-C6 | L6: =IF(COUNTIF(A$2:A6,A6)>1,1,0) | M6: =IF(COUNTIF(properties!$A$2:$A$21,B6)=0,1,0) | N6: =IF(M6=1,0,IF(G6<>INDEX(properties!$E$2:$E$21,MATCH(B6,properties!$A$2:$A$21,0)),1,0)) | O6: =IF(OR(I6>F6,AND(E6<>"cancelled",I6>0)),1,0) | P6: =IF(H6<0,1,0) | Q6: =IF(L6+M6+N6+O6=0,1,0) | R6: =IF(AND(Q6=1,E6<>"cancelled"),COUNTIFS($B$2:$B$152,B6,$Q$2:$Q$152,1,$E$2:$E$152,"<>cancelled",$C$2:$C$152,"<"&D6,$D$2:$D$152,">"&C6)-1,0) | S6: =IF(AND(Q6=1,OR(R6>0,P6=1)),1,0) | T6: =IF(Q6=0,0,IF(AND(S6=1,Dashboard!$C$7="Нет"),0,1)) | U6: =IF(L6=1,"Исключено: дубль",IF(M6=1,"Исключено: нет объекта",IF(N6=1,"Исключено: валюта",IF(O6=1,"Исключено: возврат/статус",IF(S6=1,"На проверке","OK"))))) | V6: =SUMIFS(commission_rules!$D$2:$D$21,commission_rules!$A$2:$A$21,B6,commission_rules!$B$2:$B$21,"<="&C6,commission_rules!$C$2:$C$21,">="&C6) | W6: =F6-I6 | X6: =IF(F6=0,0,H6*W6/F6) | Y6: =V6*W6 | Z6: =W6-X6 | AA6: =SUMIFS(calc_payments!$N$2:$N$77,calc_payments!$B$2:$B$77,A6) | AB6: =AA6-Z6 | AC6: =IF(T6=0,"",IF(AA6=0,IF(Z6=0,"нечего получать","нет платежа"),IF(ABS(AB6)<1,"сходится","расхождение"))) | AD6: =MAX(0,MIN(D6,Dashboard!$C$6+1)-MAX(C6,Dashboard!$C$5)) | AE6: =IF(K6=0,0,AD6/K6)*T6 | AF6: =F6*AE6 | AG6: =I6*AE6 | AH6: =W6*AE6 | AI6: =X6*AE6 | AJ6: =Y6*AE6 | AK6: =IF(AND(T6=1,AD6>0),1,0) | AL6: =Z6*AK6 | AM6: =AA6*AK6 | AN6: =AD6*T6 | AO6: =S6*AK6
A7: =raw_reservations!A7 | B7: =raw_reservations!B7 | C7: =raw_reservations!C7 | D7: =raw_reservations!D7 | E7: =raw_reservations!E7 | F7: =raw_reservations!F7 | G7: =raw_reservations!G7 | H7: =raw_reservations!H7 | ... J7: =raw_reservations!J7 | K7: =D7-C7 | L7: =IF(COUNTIF(A$2:A7,A7)>1,1,0) | M7: =IF(COUNTIF(properties!$A$2:$A$21,B7)=0,1,0) | N7: =IF(M7=1,0,IF(G7<>INDEX(properties!$E$2:$E$21,MATCH(B7,properties!$A$2:$A$21,0)),1,0)) | O7: =IF(OR(I7>F7,AND(E7<>"cancelled",I7>0)),1,0) | P7: =IF(H7<0,1,0) | Q7: =IF(L7+M7+N7+O7=0,1,0) | R7: =IF(AND(Q7=1,E7<>"cancelled"),COUNTIFS($B$2:$B$152,B7,$Q$2:$Q$152,1,$E$2:$E$152,"<>cancelled",$C$2:$C$152,"<"&D7,$D$2:$D$152,">"&C7)-1,0) | S7: =IF(AND(Q7=1,OR(R7>0,P7=1)),1,0) | T7: =IF(Q7=0,0,IF(AND(S7=1,Dashboard!$C$7="Нет"),0,1)) | U7: =IF(L7=1,"Исключено: дубль",IF(M7=1,"Исключено: нет объекта",IF(N7=1,"Исключено: валюта",IF(O7=1,"Исключено: возврат/статус",IF(S7=1,"На проверке","OK"))))) | V7: =SUMIFS(commission_rules!$D$2:$D$21,commission_rules!$A$2:$A$21,B7,commission_rules!$B$2:$B$21,"<="&C7,commission_rules!$C$2:$C$21,">="&C7) | W7: =F7-I7 | X7: =IF(F7=0,0,H7*W7/F7) | Y7: =V7*W7 | Z7: =W7-X7 | AA7: =SUMIFS(calc_payments!$N$2:$N$77,calc_payments!$B$2:$B$77,A7) | AB7: =AA7-Z7 | AC7: =IF(T7=0,"",IF(AA7=0,IF(Z7=0,"нечего получать","нет платежа"),IF(ABS(AB7)<1,"сходится","расхождение"))) | AD7: =MAX(0,MIN(D7,Dashboard!$C$6+1)-MAX(C7,Dashboard!$C$5)) | AE7: =IF(K7=0,0,AD7/K7)*T7 | AF7: =F7*AE7 | AG7: =I7*AE7 | AH7: =W7*AE7 | AI7: =X7*AE7 | AJ7: =Y7*AE7 | AK7: =IF(AND(T7=1,AD7>0),1,0) | AL7: =Z7*AK7 | AM7: =AA7*AK7 | AN7: =AD7*T7 | AO7: =S7*AK7
A8: =raw_reservations!A8 | B8: =raw_reservations!B8 | C8: =raw_reservations!C8 | D8: =raw_reservations!D8 | E8: =raw_reservations!E8 | F8: =raw_reservations!F8 | G8: =raw_reservations!G8 | H8: =raw_reservations!H8 | ... J8: =raw_reservations!J8 | K8: =D8-C8 | L8: =IF(COUNTIF(A$2:A8,A8)>1,1,0) | M8: =IF(COUNTIF(properties!$A$2:$A$21,B8)=0,1,0) | N8: =IF(M8=1,0,IF(G8<>INDEX(properties!$E$2:$E$21,MATCH(B8,properties!$A$2:$A$21,0)),1,0)) | O8: =IF(OR(I8>F8,AND(E8<>"cancelled",I8>0)),1,0) | P8: =IF(H8<0,1,0) | Q8: =IF(L8+M8+N8+O8=0,1,0) | R8: =IF(AND(Q8=1,E8<>"cancelled"),COUNTIFS($B$2:$B$152,B8,$Q$2:$Q$152,1,$E$2:$E$152,"<>cancelled",$C$2:$C$152,"<"&D8,$D$2:$D$152,">"&C8)-1,0) | S8: =IF(AND(Q8=1,OR(R8>0,P8=1)),1,0) | T8: =IF(Q8=0,0,IF(AND(S8=1,Dashboard!$C$7="Нет"),0,1)) | U8: =IF(L8=1,"Исключено: дубль",IF(M8=1,"Исключено: нет объекта",IF(N8=1,"Исключено: валюта",IF(O8=1,"Исключено: возврат/статус",IF(S8=1,"На проверке","OK"))))) | V8: =SUMIFS(commission_rules!$D$2:$D$21,commission_rules!$A$2:$A$21,B8,commission_rules!$B$2:$B$21,"<="&C8,commission_rules!$C$2:$C$21,">="&C8) | W8: =F8-I8 | X8: =IF(F8=0,0,H8*W8/F8) | Y8: =V8*W8 | Z8: =W8-X8 | AA8: =SUMIFS(calc_payments!$N$2:$N$77,calc_payments!$B$2:$B$77,A8) | AB8: =AA8-Z8 | AC8: =IF(T8=0,"",IF(AA8=0,IF(Z8=0,"нечего получать","нет платежа"),IF(ABS(AB8)<1,"сходится","расхождение"))) | AD8: =MAX(0,MIN(D8,Dashboard!$C$6+1)-MAX(C8,Dashboard!$C$5)) | AE8: =IF(K8=0,0,AD8/K8)*T8 | AF8: =F8*AE8 | AG8: =I8*AE8 | AH8: =W8*AE8 | AI8: =X8*AE8 | AJ8: =Y8*AE8 | AK8: =IF(AND(T8=1,AD8>0),1,0) | AL8: =Z8*AK8 | AM8: =AA8*AK8 | AN8: =AD8*T8 | AO8: =S8*AK8
A9: =raw_reservations!A9 | B9: =raw_reservations!B9 | C9: =raw_reservations!C9 | D9: =raw_reservations!D9 | E9: =raw_reservations!E9 | F9: =raw_reservations!F9 | G9: =raw_reservations!G9 | H9: =raw_reservations!H9 | ... J9: =raw_reservations!J9 | K9: =D9-C9 | L9: =IF(COUNTIF(A$2:A9,A9)>1,1,0) | M9: =IF(COUNTIF(properties!$A$2:$A$21,B9)=0,1,0) | N9: =IF(M9=1,0,IF(G9<>INDEX(properties!$E$2:$E$21,MATCH(B9,properties!$A$2:$A$21,0)),1,0)) | O9: =IF(OR(I9>F9,AND(E9<>"cancelled",I9>0)),1,0) | P9: =IF(H9<0,1,0) | Q9: =IF(L9+M9+N9+O9=0,1,0) | R9: =IF(AND(Q9=1,E9<>"cancelled"),COUNTIFS($B$2:$B$152,B9,$Q$2:$Q$152,1,$E$2:$E$152,"<>cancelled",$C$2:$C$152,"<"&D9,$D$2:$D$152,">"&C9)-1,0) | S9: =IF(AND(Q9=1,OR(R9>0,P9=1)),1,0) | T9: =IF(Q9=0,0,IF(AND(S9=1,Dashboard!$C$7="Нет"),0,1)) | U9: =IF(L9=1,"Исключено: дубль",IF(M9=1,"Исключено: нет объекта",IF(N9=1,"Исключено: валюта",IF(O9=1,"Исключено: возврат/статус",IF(S9=1,"На проверке","OK"))))) | V9: =SUMIFS(commission_rules!$D$2:$D$21,commission_rules!$A$2:$A$21,B9,commission_rules!$B$2:$B$21,"<="&C9,commission_rules!$C$2:$C$21,">="&C9) | W9: =F9-I9 | X9: =IF(F9=0,0,H9*W9/F9) | Y9: =V9*W9 | Z9: =W9-X9 | AA9: =SUMIFS(calc_payments!$N$2:$N$77,calc_payments!$B$2:$B$77,A9) | AB9: =AA9-Z9 | AC9: =IF(T9=0,"",IF(AA9=0,IF(Z9=0,"нечего получать","нет платежа"),IF(ABS(AB9)<1,"сходится","расхождение"))) | AD9: =MAX(0,MIN(D9,Dashboard!$C$6+1)-MAX(C9,Dashboard!$C$5)) | AE9: =IF(K9=0,0,AD9/K9)*T9 | AF9: =F9*AE9 | AG9: =I9*AE9 | AH9: =W9*AE9 | AI9: =X9*AE9 | AJ9: =Y9*AE9 | AK9: =IF(AND(T9=1,AD9>0),1,0) | AL9: =Z9*AK9 | AM9: =AA9*AK9 | AN9: =AD9*T9 | AO9: =S9*AK9
A10: =raw_reservations!A10 | B10: =raw_reservations!B10 | C10: =raw_reservations!C10 | D10: =raw_reservations!D10 | E10: =raw_reservations!E10 | F10: =raw_reservations!F10 | G10: =raw_reservations!G10 | H10: =raw_reservations!H10 | ... J10: =raw_reservations!J10 | K10: =D10-C10 | L10: =IF(COUNTIF(A$2:A10,A10)>1,1,0) | M10: =IF(COUNTIF(properties!$A$2:$A$21,B10)=0,1,0) | N10: =IF(M10=1,0,IF(G10<>INDEX(properties!$E$2:$E$21,MATCH(B10,properties!$A$2:$A$21,0)),1,0)) | O10: =IF(OR(I10>F10,AND(E10<>"cancelled",I10>0)),1,0) | P10: =IF(H10<0,1,0) | Q10: =IF(L10+M10+N10+O10=0,1,0) | R10: =IF(AND(Q10=1,E10<>"cancelled"),COUNTIFS($B$2:$B$152,B10,$Q$2:$Q$152,1,$E$2:$E$152,"<>cancelled",$C$2:$C$152,"<"&D10,$D$2:$D$152,">"&C10)-1,0) | S10: =IF(AND(Q10=1,OR(R10>0,P10=1)),1,0) | T10: =IF(Q10=0,0,IF(AND(S10=1,Dashboard!$C$7="Нет"),0,1)) | U10: =IF(L10=1,"Исключено: дубль",IF(M10=1,"Исключено: нет объекта",IF(N10=1,"Исключено: валюта",IF(O10=1,"Исключено: возврат/статус",IF(S10=1,"На проверке","OK"))))) | V10: =SUMIFS(commission_rules!$D$2:$D$21,commission_rules!$A$2:$A$21,B10,commission_rules!$B$2:$B$21,"<="&C10,commission_rules!$C$2:$C$21,">="&C10) | W10: =F10-I10 | X10: =IF(F10=0,0,H10*W10/F10) | Y10: =V10*W10 | Z10: =W10-X10 | AA10: =SUMIFS(calc_payments!$N$2:$N$77,calc_payments!$B$2:$B$77,A10) | AB10: =AA10-Z10 | AC10: =IF(T10=0,"",IF(AA10=0,IF(Z10=0,"нечего получать","нет платежа"),IF(ABS(AB10)<1,"сходится","расхождение"))) | AD10: =MAX(0,MIN(D10,Dashboard!$C$6+1)-MAX(C10,Dashboard!$C$5)) | AE10: =IF(K10=0,0,AD10/K10)*T10 | AF10: =F10*AE10 | AG10: =I10*AE10 | AH10: =W10*AE10 | AI10: =X10*AE10 | AJ10: =Y10*AE10 | AK10: =IF(AND(T10=1,AD10>0),1,0) | AL10: =Z10*AK10 | AM10: =AA10*AK10 | AN10: =AD10*T10 | AO10: =S10*AK10
A11: =raw_reservations!A11 | B11: =raw_reservations!B11 | C11: =raw_reservations!C11 | D11: =raw_reservations!D11 | E11: =raw_reservations!E11 | F11: =raw_reservations!F11 | G11: =raw_reservations!G11 | H11: =raw_reservations!H11 | ... J11: =raw_reservations!J11 | K11: =D11-C11 | L11: =IF(COUNTIF(A$2:A11,A11)>1,1,0) | M11: =IF(COUNTIF(properties!$A$2:$A$21,B11)=0,1,0) | N11: =IF(M11=1,0,IF(G11<>INDEX(properties!$E$2:$E$21,MATCH(B11,properties!$A$2:$A$21,0)),1,0)) | O11: =IF(OR(I11>F11,AND(E11<>"cancelled",I11>0)),1,0) | P11: =IF(H11<0,1,0) | Q11: =IF(L11+M11+N11+O11=0,1,0) | R11: =IF(AND(Q11=1,E11<>"cancelled"),COUNTIFS($B$2:$B$152,B11,$Q$2:$Q$152,1,$E$2:$E$152,"<>cancelled",$C$2:$C$152,"<"&D11,$D$2:$D$152,">"&C11)-1,0) | S11: =IF(AND(Q11=1,OR(R11>0,P11=1)),1,0) | T11: =IF(Q11=0,0,IF(AND(S11=1,Dashboard!$C$7="Нет"),0,1)) | U11: =IF(L11=1,"Исключено: дубль",IF(M11=1,"Исключено: нет объекта",IF(N11=1,"Исключено: валюта",IF(O11=1,"Исключено: возврат/статус",IF(S11=1,"На проверке","OK"))))) | V11: =SUMIFS(commission_rules!$D$2:$D$21,commission_rules!$A$2:$A$21,B11,commission_rules!$B$2:$B$21,"<="&C11,commission_rules!$C$2:$C$21,">="&C11) | W11: =F11-I11 | X11: =IF(F11=0,0,H11*W11/F11) | Y11: =V11*W11 | Z11: =W11-X11 | AA11: =SUMIFS(calc_payments!$N$2:$N$77,calc_payments!$B$2:$B$77,A11) | AB11: =AA11-Z11 | AC11: =IF(T11=0,"",IF(AA11=0,IF(Z11=0,"нечего получать","нет платежа"),IF(ABS(AB11)<1,"сходится","расхождение"))) | AD11: =MAX(0,MIN(D11,Dashboard!$C$6+1)-MAX(C11,Dashboard!$C$5)) | AE11: =IF(K11=0,0,AD11/K11)*T11 | AF11: =F11*AE11 | AG11: =I11*AE11 | AH11: =W11*AE11 | AI11: =X11*AE11 | AJ11: =Y11*AE11 | AK11: =IF(AND(T11=1,AD11>0),1,0) | AL11: =Z11*AK11 | AM11: =AA11*AK11 | AN11: =AD11*T11 | AO11: =S11*AK11
A12: =raw_reservations!A12 | B12: =raw_reservations!B12 | C12: =raw_reservations!C12 | D12: =raw_reservations!D12 | E12: =raw_reservations!E12 | F12: =raw_reservations!F12 | G12: =raw_reservations!G12 | H12: =raw_reservations!H12 | ... J12: =raw_reservations!J12 | K12: =D12-C12 | L12: =IF(COUNTIF(A$2:A12,A12)>1,1,0) | M12: =IF(COUNTIF(properties!$A$2:$A$21,B12)=0,1,0) | N12: =IF(M12=1,0,IF(G12<>INDEX(properties!$E$2:$E$21,MATCH(B12,properties!$A$2:$A$21,0)),1,0)) | O12: =IF(OR(I12>F12,AND(E12<>"cancelled",I12>0)),1,0) | P12: =IF(H12<0,1,0) | Q12: =IF(L12+M12+N12+O12=0,1,0) | R12: =IF(AND(Q12=1,E12<>"cancelled"),COUNTIFS($B$2:$B$152,B12,$Q$2:$Q$152,1,$E$2:$E$152,"<>cancelled",$C$2:$C$152,"<"&D12,$D$2:$D$152,">"&C12)-1,0) | S12: =IF(AND(Q12=1,OR(R12>0,P12=1)),1,0) | T12: =IF(Q12=0,0,IF(AND(S12=1,Dashboard!$C$7="Нет"),0,1)) | U12: =IF(L12=1,"Исключено: дубль",IF(M12=1,"Исключено: нет объекта",IF(N12=1,"Исключено: валюта",IF(O12=1,"Исключено: возврат/статус",IF(S12=1,"На проверке","OK"))))) | V12: =SUMIFS(commission_rules!$D$2:$D$21,commission_rules!$A$2:$A$21,B12,commission_rules!$B$2:$B$21,"<="&C12,commission_rules!$C$2:$C$21,">="&C12) | W12: =F12-I12 | X12: =IF(F12=0,0,H12*W12/F12) | Y12: =V12*W12 | Z12: =W12-X12 | AA12: =SUMIFS(calc_payments!$N$2:$N$77,calc_payments!$B$2:$B$77,A12) | AB12: =AA12-Z12 | AC12: =IF(T12=0,"",IF(AA12=0,IF(Z12=0,"нечего получать","нет платежа"),IF(ABS(AB12)<1,"сходится","расхождение"))) | AD12: =MAX(0,MIN(D12,Dashboard!$C$6+1)-MAX(C12,Dashboard!$C$5)) | AE12: =IF(K12=0,0,AD12/K12)*T12 | AF12: =F12*AE12 | AG12: =I12*AE12 | AH12: =W12*AE12 | AI12: =X12*AE12 | AJ12: =Y12*AE12 | AK12: =IF(AND(T12=1,AD12>0),1,0) | AL12: =Z12*AK12 | AM12: =AA12*AK12 | AN12: =AD12*T12 | AO12: =S12*AK12
A13: =raw_reservations!A13 | B13: =raw_reservations!B13 | C13: =raw_reservations!C13 | D13: =raw_reservations!D13 | E13: =raw_reservations!E13 | F13: =raw_reservations!F13 | G13: =raw_reservations!G13 | H13: =raw_reservations!H13 | ... J13: =raw_reservations!J13 | K13: =D13-C13 | L13: =IF(COUNTIF(A$2:A13,A13)>1,1,0) | M13: =IF(COUNTIF(properties!$A$2:$A$21,B13)=0,1,0) | N13: =IF(M13=1,0,IF(G13<>INDEX(properties!$E$2:$E$21,MATCH(B13,properties!$A$2:$A$21,0)),1,0)) | O13: =IF(OR(I13>F13,AND(E13<>"cancelled",I13>0)),1,0) | P13: =IF(H13<0,1,0) | Q13: =IF(L13+M13+N13+O13=0,1,0) | R13: =IF(AND(Q13=1,E13<>"cancelled"),COUNTIFS($B$2:$B$152,B13,$Q$2:$Q$152,1,$E$2:$E$152,"<>cancelled",$C$2:$C$152,"<"&D13,$D$2:$D$152,">"&C13)-1,0) | S13: =IF(AND(Q13=1,OR(R13>0,P13=1)),1,0) | T13: =IF(Q13=0,0,IF(AND(S13=1,Dashboard!$C$7="Нет"),0,1)) | U13: =IF(L13=1,"Исключено: дубль",IF(M13=1,"Исключено: нет объекта",IF(N13=1,"Исключено: валюта",IF(O13=1,"Исключено: возврат/статус",IF(S13=1,"На проверке","OK"))))) | V13: =SUMIFS(commission_rules!$D$2:$D$21,commission_rules!$A$2:$A$21,B13,commission_rules!$B$2:$B$21,"<="&C13,commission_rules!$C$2:$C$21,">="&C13) | W13: =F13-I13 | X13: =IF(F13=0,0,H13*W13/F13) | Y13: =V13*W13 | Z13: =W13-X13 | AA13: =SUMIFS(calc_payments!$N$2:$N$77,calc_payments!$B$2:$B$77,A13) | AB13: =AA13-Z13 | AC13: =IF(T13=0,"",IF(AA13=0,IF(Z13=0,"нечего получать","нет платежа"),IF(ABS(AB13)<1,"сходится","расхождение"))) | AD13: =MAX(0,MIN(D13,Dashboard!$C$6+1)-MAX(C13,Dashboard!$C$5)) | AE13: =IF(K13=0,0,AD13/K13)*T13 | AF13: =F13*AE13 | AG13: =I13*AE13 | AH13: =W13*AE13 | AI13: =X13*AE13 | AJ13: =Y13*AE13 | AK13: =IF(AND(T13=1,AD13>0),1,0) | AL13: =Z13*AK13 | AM13: =AA13*AK13 | AN13: =AD13*T13 | AO13: =S13*AK13
... A152: =raw_reservations!A152 | B152: =raw_reservations!B152 | C152: =raw_reservations!C152 | D152: =raw_reservations!D152 | E152: =raw_reservations!E152 | F152: =raw_reservations!F152 | G152: =raw_reservations!G152 | H152: =raw_reservations!H152 | ... J152: =raw_reservations!J152 | K152: =D152-C152 | L152: =IF(COUNTIF(A$2:A152,A152)>1,1,0) | M152: =IF(COUNTIF(properties!$A$2:$A$21,B152)=0,1,0) | N152: =IF(M152=1,0,IF(G152<>INDEX(properties!$E$2:$E$21,MATCH(B152,properties!$A$2:$A$21,0)),1,0)) | O152: =IF(OR(I152>F152,AND(E152<>"cancelled",I152>0)),1,0) | P152: =IF(H152<0,1,0) | Q152: =IF(L152+M152+N152+O152=0,1,0) | R152: =IF(AND(Q152=1,E152<>"cancelled"),COUNTIFS($B$2:$B$152,B152,$Q$2:$Q$152,1,$E$2:$E$152,"<>cancelled",$C$2:$C$152,"<"&D152,$D$2:$D$152,">"&C152)-1,0) | S152: =IF(AND(Q152=1,OR(R152>0,P152=1)),1,0) | T152: =IF(Q152=0,0,IF(AND(S152=1,Dashboard!$C$7="Нет"),0,1)) | U152: =IF(L152=1,"Исключено: дубль",IF(M152=1,"Исключено: нет объекта",IF(N152=1,"Исключено: валюта",IF(O152=1,"Исключено: возврат/статус",IF(S152=1,"На проверке","OK"))))) | V152: =SUMIFS(commission_rules!$D$2:$D$21,commission_rules!$A$2:$A$21,B152,commission_rules!$B$2:$B$21,"<="&C152,commission_rules!$C$2:$C$21,">="&C152) | W152: =F152-I152 | X152: =IF(F152=0,0,H152*W152/F152) | Y152: =V152*W152 | Z152: =W152-X152 | AA152: =SUMIFS(calc_payments!$N$2:$N$77,calc_payments!$B$2:$B$77,A152) | AB152: =AA152-Z152 | AC152: =IF(T152=0,"",IF(AA152=0,IF(Z152=0,"нечего получать","нет платежа"),IF(ABS(AB152)<1,"сходится","расхождение"))) | AD152: =MAX(0,MIN(D152,Dashboard!$C$6+1)-MAX(C152,Dashboard!$C$5)) | AE152: =IF(K152=0,0,AD152/K152)*T152 | AF152: =F152*AE152 | AG152: =I152*AE152 | AH152: =W152*AE152 | AI152: =X152*AE152 | AJ152: =Y152*AE152 | AK152: =IF(AND(T152=1,AD152>0),1,0) | AL152: =Z152*AK152 | AM152: =AA152*AK152 | AN152: =AD152*T152 | AO152: =S152*AK152

Sheet calc_payments
A1: payment_id | B1: reservation_id | C1: property_id | D1: payment_date | E1: amount | F1: currency | G1: status | H1: chk: дубль ID | I1: chk: нет объекта | J1: chk: сумма = 0 | K1: chk: бронь не найдена | L1: chk: объект ≠ брони | M1: в расчёте | N1: сумма в расчёте | O1: в периоде | P1: поступило · период | Q1: решение
A2: =raw_payments!A2 | B2: =raw_payments!B2 | C2: =raw_payments!C2 | D2: =raw_payments!D2 | E2: =raw_payments!E2 | F2: =raw_payments!F2 | G2: =raw_payments!G2 | H2: =IF(COUNTIF(A$2:A2,A2)>1,1,0) | I2: =IF(COUNTIF(properties!$A$2:$A$21,C2)=0,1,0) | J2: =IF(E2<=0,1,0) | K2: =IF(COUNTIF(raw_reservations!$A$2:$A$152,B2)=0,1,0) | L2: =IF(K2=1,0,IF(INDEX(raw_reservations!$B$2:$B$152,MATCH(B2,raw_reservations!$A$2:$A$152,0))<>C2,1,0)) | M2: =IF(AND(H2=0,I2=0,J2=0,K2=0,G2="received"),1,0) | N2: =E2*M2 | O2: =IF(AND(D2>=Dashboard!$C$5,D2<=Dashboard!$C$6),1,0) | P2: =N2*O2 | Q2: =IF(H2=1,"Исключено: дубль",IF(I2=1,"Исключено: нет объекта",IF(K2=1,"Исключено: нет брони",IF(J2=1,"Исключено: сумма 0","OK"))))
A3: =raw_payments!A3 | B3: =raw_payments!B3 | C3: =raw_payments!C3 | D3: =raw_payments!D3 | E3: =raw_payments!E3 | F3: =raw_payments!F3 | G3: =raw_payments!G3 | H3: =IF(COUNTIF(A$2:A3,A3)>1,1,0) | I3: =IF(COUNTIF(properties!$A$2:$A$21,C3)=0,1,0) | J3: =IF(E3<=0,1,0) | K3: =IF(COUNTIF(raw_reservations!$A$2:$A$152,B3)=0,1,0) | L3: =IF(K3=1,0,IF(INDEX(raw_reservations!$B$2:$B$152,MATCH(B3,raw_reservations!$A$2:$A$152,0))<>C3,1,0)) | M3: =IF(AND(H3=0,I3=0,J3=0,K3=0,G3="received"),1,0) | N3: =E3*M3 | O3: =IF(AND(D3>=Dashboard!$C$5,D3<=Dashboard!$C$6),1,0) | P3: =N3*O3 | Q3: =IF(H3=1,"Исключено: дубль",IF(I3=1,"Исключено: нет объекта",IF(K3=1,"Исключено: нет брони",IF(J3=1,"Исключено: сумма 0","OK"))))
A4: =raw_payments!A4 | B4: =raw_payments!B4 | C4: =raw_payments!C4 | D4: =raw_payments!D4 | E4: =raw_payments!E4 | F4: =raw_payments!F4 | G4: =raw_payments!G4 | H4: =IF(COUNTIF(A$2:A4,A4)>1,1,0) | I4: =IF(COUNTIF(properties!$A$2:$A$21,C4)=0,1,0) | J4: =IF(E4<=0,1,0) | K4: =IF(COUNTIF(raw_reservations!$A$2:$A$152,B4)=0,1,0) | L4: =IF(K4=1,0,IF(INDEX(raw_reservations!$B$2:$B$152,MATCH(B4,raw_reservations!$A$2:$A$152,0))<>C4,1,0)) | M4: =IF(AND(H4=0,I4=0,J4=0,K4=0,G4="received"),1,0) | N4: =E4*M4 | O4: =IF(AND(D4>=Dashboard!$C$5,D4<=Dashboard!$C$6),1,0) | P4: =N4*O4 | Q4: =IF(H4=1,"Исключено: дубль",IF(I4=1,"Исключено: нет объекта",IF(K4=1,"Исключено: нет брони",IF(J4=1,"Исключено: сумма 0","OK"))))
A5: =raw_payments!A5 | B5: =raw_payments!B5 | C5: =raw_payments!C5 | D5: =raw_payments!D5 | E5: =raw_payments!E5 | F5: =raw_payments!F5 | G5: =raw_payments!G5 | H5: =IF(COUNTIF(A$2:A5,A5)>1,1,0) | I5: =IF(COUNTIF(properties!$A$2:$A$21,C5)=0,1,0) | J5: =IF(E5<=0,1,0) | K5: =IF(COUNTIF(raw_reservations!$A$2:$A$152,B5)=0,1,0) | L5: =IF(K5=1,0,IF(INDEX(raw_reservations!$B$2:$B$152,MATCH(B5,raw_reservations!$A$2:$A$152,0))<>C5,1,0)) | M5: =IF(AND(H5=0,I5=0,J5=0,K5=0,G5="received"),1,0) | N5: =E5*M5 | O5: =IF(AND(D5>=Dashboard!$C$5,D5<=Dashboard!$C$6),1,0) | P5: =N5*O5 | Q5: =IF(H5=1,"Исключено: дубль",IF(I5=1,"Исключено: нет объекта",IF(K5=1,"Исключено: нет брони",IF(J5=1,"Исключено: сумма 0","OK"))))
A6: =raw_payments!A6 | B6: =raw_payments!B6 | C6: =raw_payments!C6 | D6: =raw_payments!D6 | E6: =raw_payments!E6 | F6: =raw_payments!F6 | G6: =raw_payments!G6 | H6: =IF(COUNTIF(A$2:A6,A6)>1,1,0) | I6: =IF(COUNTIF(properties!$A$2:$A$21,C6)=0,1,0) | J6: =IF(E6<=0,1,0) | K6: =IF(COUNTIF(raw_reservations!$A$2:$A$152,B6)=0,1,0) | L6: =IF(K6=1,0,IF(INDEX(raw_reservations!$B$2:$B$152,MATCH(B6,raw_reservations!$A$2:$A$152,0))<>C6,1,0)) | M6: =IF(AND(H6=0,I6=0,J6=0,K6=0,G6="received"),1,0) | N6: =E6*M6 | O6: =IF(AND(D6>=Dashboard!$C$5,D6<=Dashboard!$C$6),1,0) | P6: =N6*O6 | Q6: =IF(H6=1,"Исключено: дубль",IF(I6=1,"Исключено: нет объекта",IF(K6=1,"Исключено: нет брони",IF(J6=1,"Исключено: сумма 0","OK"))))
A7: =raw_payments!A7 | B7: =raw_payments!B7 | C7: =raw_payments!C7 | D7: =raw_payments!D7 | E7: =raw_payments!E7 | F7: =raw_payments!F7 | G7: =raw_payments!G7 | H7: =IF(COUNTIF(A$2:A7,A7)>1,1,0) | I7: =IF(COUNTIF(properties!$A$2:$A$21,C7)=0,1,0) | J7: =IF(E7<=0,1,0) | K7: =IF(COUNTIF(raw_reservations!$A$2:$A$152,B7)=0,1,0) | L7: =IF(K7=1,0,IF(INDEX(raw_reservations!$B$2:$B$152,MATCH(B7,raw_reservations!$A$2:$A$152,0))<>C7,1,0)) | M7: =IF(AND(H7=0,I7=0,J7=0,K7=0,G7="received"),1,0) | N7: =E7*M7 | O7: =IF(AND(D7>=Dashboard!$C$5,D7<=Dashboard!$C$6),1,0) | P7: =N7*O7 | Q7: =IF(H7=1,"Исключено: дубль",IF(I7=1,"Исключено: нет объекта",IF(K7=1,"Исключено: нет брони",IF(J7=1,"Исключено: сумма 0","OK"))))
A8: =raw_payments!A8 | B8: =raw_payments!B8 | C8: =raw_payments!C8 | D8: =raw_payments!D8 | E8: =raw_payments!E8 | F8: =raw_payments!F8 | G8: =raw_payments!G8 | H8: =IF(COUNTIF(A$2:A8,A8)>1,1,0) | I8: =IF(COUNTIF(properties!$A$2:$A$21,C8)=0,1,0) | J8: =IF(E8<=0,1,0) | K8: =IF(COUNTIF(raw_reservations!$A$2:$A$152,B8)=0,1,0) | L8: =IF(K8=1,0,IF(INDEX(raw_reservations!$B$2:$B$152,MATCH(B8,raw_reservations!$A$2:$A$152,0))<>C8,1,0)) | M8: =IF(AND(H8=0,I8=0,J8=0,K8=0,G8="received"),1,0) | N8: =E8*M8 | O8: =IF(AND(D8>=Dashboard!$C$5,D8<=Dashboard!$C$6),1,0) | P8: =N8*O8 | Q8: =IF(H8=1,"Исключено: дубль",IF(I8=1,"Исключено: нет объекта",IF(K8=1,"Исключено: нет брони",IF(J8=1,"Исключено: сумма 0","OK"))))
A9: =raw_payments!A9 | B9: =raw_payments!B9 | C9: =raw_payments!C9 | D9: =raw_payments!D9 | E9: =raw_payments!E9 | F9: =raw_payments!F9 | G9: =raw_payments!G9 | H9: =IF(COUNTIF(A$2:A9,A9)>1,1,0) | I9: =IF(COUNTIF(properties!$A$2:$A$21,C9)=0,1,0) | J9: =IF(E9<=0,1,0) | K9: =IF(COUNTIF(raw_reservations!$A$2:$A$152,B9)=0,1,0) | L9: =IF(K9=1,0,IF(INDEX(raw_reservations!$B$2:$B$152,MATCH(B9,raw_reservations!$A$2:$A$152,0))<>C9,1,0)) | M9: =IF(AND(H9=0,I9=0,J9=0,K9=0,G9="received"),1,0) | N9: =E9*M9 | O9: =IF(AND(D9>=Dashboard!$C$5,D9<=Dashboard!$C$6),1,0) | P9: =N9*O9 | Q9: =IF(H9=1,"Исключено: дубль",IF(I9=1,"Исключено: нет объекта",IF(K9=1,"Исключено: нет брони",IF(J9=1,"Исключено: сумма 0","OK"))))
A10: =raw_payments!A10 | B10: =raw_payments!B10 | C10: =raw_payments!C10 | D10: =raw_payments!D10 | E10: =raw_payments!E10 | F10: =raw_payments!F10 | G10: =raw_payments!G10 | H10: =IF(COUNTIF(A$2:A10,A10)>1,1,0) | I10: =IF(COUNTIF(properties!$A$2:$A$21,C10)=0,1,0) | J10: =IF(E10<=0,1,0) | K10: =IF(COUNTIF(raw_reservations!$A$2:$A$152,B10)=0,1,0) | L10: =IF(K10=1,0,IF(INDEX(raw_reservations!$B$2:$B$152,MATCH(B10,raw_reservations!$A$2:$A$152,0))<>C10,1,0)) | M10: =IF(AND(H10=0,I10=0,J10=0,K10=0,G10="received"),1,0) | N10: =E10*M10 | O10: =IF(AND(D10>=Dashboard!$C$5,D10<=Dashboard!$C$6),1,0) | P10: =N10*O10 | Q10: =IF(H10=1,"Исключено: дубль",IF(I10=1,"Исключено: нет объекта",IF(K10=1,"Исключено: нет брони",IF(J10=1,"Исключено: сумма 0","OK"))))
A11: =raw_payments!A11 | B11: =raw_payments!B11 | C11: =raw_payments!C11 | D11: =raw_payments!D11 | E11: =raw_payments!E11 | F11: =raw_payments!F11 | G11: =raw_payments!G11 | H11: =IF(COUNTIF(A$2:A11,A11)>1,1,0) | I11: =IF(COUNTIF(properties!$A$2:$A$21,C11)=0,1,0) | J11: =IF(E11<=0,1,0) | K11: =IF(COUNTIF(raw_reservations!$A$2:$A$152,B11)=0,1,0) | L11: =IF(K11=1,0,IF(INDEX(raw_reservations!$B$2:$B$152,MATCH(B11,raw_reservations!$A$2:$A$152,0))<>C11,1,0)) | M11: =IF(AND(H11=0,I11=0,J11=0,K11=0,G11="received"),1,0) | N11: =E11*M11 | O11: =IF(AND(D11>=Dashboard!$C$5,D11<=Dashboard!$C$6),1,0) | P11: =N11*O11 | Q11: =IF(H11=1,"Исключено: дубль",IF(I11=1,"Исключено: нет объекта",IF(K11=1,"Исключено: нет брони",IF(J11=1,"Исключено: сумма 0","OK"))))
A12: =raw_payments!A12 | B12: =raw_payments!B12 | C12: =raw_payments!C12 | D12: =raw_payments!D12 | E12: =raw_payments!E12 | F12: =raw_payments!F12 | G12: =raw_payments!G12 | H12: =IF(COUNTIF(A$2:A12,A12)>1,1,0) | I12: =IF(COUNTIF(properties!$A$2:$A$21,C12)=0,1,0) | J12: =IF(E12<=0,1,0) | K12: =IF(COUNTIF(raw_reservations!$A$2:$A$152,B12)=0,1,0) | L12: =IF(K12=1,0,IF(INDEX(raw_reservations!$B$2:$B$152,MATCH(B12,raw_reservations!$A$2:$A$152,0))<>C12,1,0)) | M12: =IF(AND(H12=0,I12=0,J12=0,K12=0,G12="received"),1,0) | N12: =E12*M12 | O12: =IF(AND(D12>=Dashboard!$C$5,D12<=Dashboard!$C$6),1,0) | P12: =N12*O12 | Q12: =IF(H12=1,"Исключено: дубль",IF(I12=1,"Исключено: нет объекта",IF(K12=1,"Исключено: нет брони",IF(J12=1,"Исключено: сумма 0","OK"))))
A13: =raw_payments!A13 | B13: =raw_payments!B13 | C13: =raw_payments!C13 | D13: =raw_payments!D13 | E13: =raw_payments!E13 | F13: =raw_payments!F13 | G13: =raw_payments!G13 | H13: =IF(COUNTIF(A$2:A13,A13)>1,1,0) | I13: =IF(COUNTIF(properties!$A$2:$A$21,C13)=0,1,0) | J13: =IF(E13<=0,1,0) | K13: =IF(COUNTIF(raw_reservations!$A$2:$A$152,B13)=0,1,0) | L13: =IF(K13=1,0,IF(INDEX(raw_reservations!$B$2:$B$152,MATCH(B13,raw_reservations!$A$2:$A$152,0))<>C13,1,0)) | M13: =IF(AND(H13=0,I13=0,J13=0,K13=0,G13="received"),1,0) | N13: =E13*M13 | O13: =IF(AND(D13>=Dashboard!$C$5,D13<=Dashboard!$C$6),1,0) | P13: =N13*O13 | Q13: =IF(H13=1,"Исключено: дубль",IF(I13=1,"Исключено: нет объекта",IF(K13=1,"Исключено: нет брони",IF(J13=1,"Исключено: сумма 0","OK"))))
... A77: =raw_payments!A77 | B77: =raw_payments!B77 | C77: =raw_payments!C77 | D77: =raw_payments!D77 | E77: =raw_payments!E77 | F77: =raw_payments!F77 | G77: =raw_payments!G77 | H77: =IF(COUNTIF(A$2:A77,A77)>1,1,0) | I77: =IF(COUNTIF(properties!$A$2:$A$21,C77)=0,1,0) | J77: =IF(E77<=0,1,0) | K77: =IF(COUNTIF(raw_reservations!$A$2:$A$152,B77)=0,1,0) | L77: =IF(K77=1,0,IF(INDEX(raw_reservations!$B$2:$B$152,MATCH(B77,raw_reservations!$A$2:$A$152,0))<>C77,1,0)) | M77: =IF(AND(H77=0,I77=0,J77=0,K77=0,G77="received"),1,0) | N77: =E77*M77 | O77: =IF(AND(D77>=Dashboard!$C$5,D77<=Dashboard!$C$6),1,0) | P77: =N77*O77 | Q77: =IF(H77=1,"Исключено: дубль",IF(I77=1,"Исключено: нет объекта",IF(K77=1,"Исключено: нет брони",IF(J77=1,"Исключено: сумма 0","OK"))))

Sheet calc_expenses
A1: expense_id | B1: property_id | C1: expense_date | D1: category | E1: amount | F1: currency | G1: payment_status | H1: chk: нет объекта | I1: chk: дубль ID | J1: в расчёте | K1: в периоде | L1: расход · период | M1: оплачено · период | N1: pending · период | O1: решение
A2: =raw_expenses!A2 | B2: =raw_expenses!B2 | C2: =raw_expenses!C2 | D2: =raw_expenses!D2 | E2: =raw_expenses!E2 | F2: =raw_expenses!F2 | G2: =raw_expenses!G2 | H2: =IF(COUNTIF(properties!$A$2:$A$21,B2)=0,1,0) | I2: =IF(COUNTIF(A$2:A2,A2)>1,1,0) | J2: =IF(H2+I2=0,1,0) | K2: =IF(AND(C2>=Dashboard!$C$5,C2<=Dashboard!$C$6),1,0) | L2: =E2*J2*K2 | M2: =IF(G2="paid",L2,0) | N2: =IF(G2="paid",0,L2) | O2: =IF(H2=1,"Исключено: нет объекта",IF(I2=1,"Исключено: дубль","OK"))
A3: =raw_expenses!A3 | B3: =raw_expenses!B3 | C3: =raw_expenses!C3 | D3: =raw_expenses!D3 | E3: =raw_expenses!E3 | F3: =raw_expenses!F3 | G3: =raw_expenses!G3 | H3: =IF(COUNTIF(properties!$A$2:$A$21,B3)=0,1,0) | I3: =IF(COUNTIF(A$2:A3,A3)>1,1,0) | J3: =IF(H3+I3=0,1,0) | K3: =IF(AND(C3>=Dashboard!$C$5,C3<=Dashboard!$C$6),1,0) | L3: =E3*J3*K3 | M3: =IF(G3="paid",L3,0) | N3: =IF(G3="paid",0,L3) | O3: =IF(H3=1,"Исключено: нет объекта",IF(I3=1,"Исключено: дубль","OK"))
A4: =raw_expenses!A4 | B4: =raw_expenses!B4 | C4: =raw_expenses!C4 | D4: =raw_expenses!D4 | E4: =raw_expenses!E4 | F4: =raw_expenses!F4 | G4: =raw_expenses!G4 | H4: =IF(COUNTIF(properties!$A$2:$A$21,B4)=0,1,0) | I4: =IF(COUNTIF(A$2:A4,A4)>1,1,0) | J4: =IF(H4+I4=0,1,0) | K4: =IF(AND(C4>=Dashboard!$C$5,C4<=Dashboard!$C$6),1,0) | L4: =E4*J4*K4 | M4: =IF(G4="paid",L4,0) | N4: =IF(G4="paid",0,L4) | O4: =IF(H4=1,"Исключено: нет объекта",IF(I4=1,"Исключено: дубль","OK"))
A5: =raw_expenses!A5 | B5: =raw_expenses!B5 | C5: =raw_expenses!C5 | D5: =raw_expenses!D5 | E5: =raw_expenses!E5 | F5: =raw_expenses!F5 | G5: =raw_expenses!G5 | H5: =IF(COUNTIF(properties!$A$2:$A$21,B5)=0,1,0) | I5: =IF(COUNTIF(A$2:A5,A5)>1,1,0) | J5: =IF(H5+I5=0,1,0) | K5: =IF(AND(C5>=Dashboard!$C$5,C5<=Dashboard!$C$6),1,0) | L5: =E5*J5*K5 | M5: =IF(G5="paid",L5,0) | N5: =IF(G5="paid",0,L5) | O5: =IF(H5=1,"Исключено: нет объекта",IF(I5=1,"Исключено: дубль","OK"))
A6: =raw_expenses!A6 | B6: =raw_expenses!B6 | C6: =raw_expenses!C6 | D6: =raw_expenses!D6 | E6: =raw_expenses!E6 | F6: =raw_expenses!F6 | G6: =raw_expenses!G6 | H6: =IF(COUNTIF(properties!$A$2:$A$21,B6)=0,1,0) | I6: =IF(COUNTIF(A$2:A6,A6)>1,1,0) | J6: =IF(H6+I6=0,1,0) | K6: =IF(AND(C6>=Dashboard!$C$5,C6<=Dashboard!$C$6),1,0) | L6: =E6*J6*K6 | M6: =IF(G6="paid",L6,0) | N6: =IF(G6="paid",0,L6) | O6: =IF(H6=1,"Исключено: нет объекта",IF(I6=1,"Исключено: дубль","OK"))
A7: =raw_expenses!A7 | B7: =raw_expenses!B7 | C7: =raw_expenses!C7 | D7: =raw_expenses!D7 | E7: =raw_expenses!E7 | F7: =raw_expenses!F7 | G7: =raw_expenses!G7 | H7: =IF(COUNTIF(properties!$A$2:$A$21,B7)=0,1,0) | I7: =IF(COUNTIF(A$2:A7,A7)>1,1,0) | J7: =IF(H7+I7=0,1,0) | K7: =IF(AND(C7>=Dashboard!$C$5,C7<=Dashboard!$C$6),1,0) | L7: =E7*J7*K7 | M7: =IF(G7="paid",L7,0) | N7: =IF(G7="paid",0,L7) | O7: =IF(H7=1,"Исключено: нет объекта",IF(I7=1,"Исключено: дубль","OK"))
A8: =raw_expenses!A8 | B8: =raw_expenses!B8 | C8: =raw_expenses!C8 | D8: =raw_expenses!D8 | E8: =raw_expenses!E8 | F8: =raw_expenses!F8 | G8: =raw_expenses!G8 | H8: =IF(COUNTIF(properties!$A$2:$A$21,B8)=0,1,0) | I8: =IF(COUNTIF(A$2:A8,A8)>1,1,0) | J8: =IF(H8+I8=0,1,0) | K8: =IF(AND(C8>=Dashboard!$C$5,C8<=Dashboard!$C$6),1,0) | L8: =E8*J8*K8 | M8: =IF(G8="paid",L8,0) | N8: =IF(G8="paid",0,L8) | O8: =IF(H8=1,"Исключено: нет объекта",IF(I8=1,"Исключено: дубль","OK"))
A9: =raw_expenses!A9 | B9: =raw_expenses!B9 | C9: =raw_expenses!C9 | D9: =raw_expenses!D9 | E9: =raw_expenses!E9 | F9: =raw_expenses!F9 | G9: =raw_expenses!G9 | H9: =IF(COUNTIF(properties!$A$2:$A$21,B9)=0,1,0) | I9: =IF(COUNTIF(A$2:A9,A9)>1,1,0) | J9: =IF(H9+I9=0,1,0) | K9: =IF(AND(C9>=Dashboard!$C$5,C9<=Dashboard!$C$6),1,0) | L9: =E9*J9*K9 | M9: =IF(G9="paid",L9,0) | N9: =IF(G9="paid",0,L9) | O9: =IF(H9=1,"Исключено: нет объекта",IF(I9=1,"Исключено: дубль","OK"))
A10: =raw_expenses!A10 | B10: =raw_expenses!B10 | C10: =raw_expenses!C10 | D10: =raw_expenses!D10 | E10: =raw_expenses!E10 | F10: =raw_expenses!F10 | G10: =raw_expenses!G10 | H10: =IF(COUNTIF(properties!$A$2:$A$21,B10)=0,1,0) | I10: =IF(COUNTIF(A$2:A10,A10)>1,1,0) | J10: =IF(H10+I10=0,1,0) | K10: =IF(AND(C10>=Dashboard!$C$5,C10<=Dashboard!$C$6),1,0) | L10: =E10*J10*K10 | M10: =IF(G10="paid",L10,0) | N10: =IF(G10="paid",0,L10) | O10: =IF(H10=1,"Исключено: нет объекта",IF(I10=1,"Исключено: дубль","OK"))
A11: =raw_expenses!A11 | B11: =raw_expenses!B11 | C11: =raw_expenses!C11 | D11: =raw_expenses!D11 | E11: =raw_expenses!E11 | F11: =raw_expenses!F11 | G11: =raw_expenses!G11 | H11: =IF(COUNTIF(properties!$A$2:$A$21,B11)=0,1,0) | I11: =IF(COUNTIF(A$2:A11,A11)>1,1,0) | J11: =IF(H11+I11=0,1,0) | K11: =IF(AND(C11>=Dashboard!$C$5,C11<=Dashboard!$C$6),1,0) | L11: =E11*J11*K11 | M11: =IF(G11="paid",L11,0) | N11: =IF(G11="paid",0,L11) | O11: =IF(H11=1,"Исключено: нет объекта",IF(I11=1,"Исключено: дубль","OK"))
A12: =raw_expenses!A12 | B12: =raw_expenses!B12 | C12: =raw_expenses!C12 | D12: =raw_expenses!D12 | E12: =raw_expenses!E12 | F12: =raw_expenses!F12 | G12: =raw_expenses!G12 | H12: =IF(COUNTIF(properties!$A$2:$A$21,B12)=0,1,0) | I12: =IF(COUNTIF(A$2:A12,A12)>1,1,0) | J12: =IF(H12+I12=0,1,0) | K12: =IF(AND(C12>=Dashboard!$C$5,C12<=Dashboard!$C$6),1,0) | L12: =E12*J12*K12 | M12: =IF(G12="paid",L12,0) | N12: =IF(G12="paid",0,L12) | O12: =IF(H12=1,"Исключено: нет объекта",IF(I12=1,"Исключено: дубль","OK"))
